Workbook

Sheet PlantData
A1: Ann. MWh, EIA 100 oldest PV systems. Some oldies were excluded; their size kept changing (Springerville, Prescott), or they're solar thermal (SEGS), or mislabeled (Saguaro), or just stunk (a few ran sporadically for 1-5 yrs, then vanished) | R1: =AVERAGE(R7:R106) -> 14.923 | X1: max> | Y1: =MAX(Y7:Y106) -> 0.099685065 | AJ1: Top 12 states w/more than 1% (8 more states had 1 system apiece) | AT1: Tracker | AU1: Fixed | AX1: {=LOGEST(BB2:BQ2,BB6:BQ6)} -> 0.93171844 | AY1: 0.93218689 | AZ1: {=LOGEST(BB4:BQ4,BB6:BQ6,TRUE,FALSE)} -> 0.97183292 | BA1: 1.0800084 | BB1: PI, by year, with user's degradation allowance included as a user input variable (try 0% degr to see a fanning cloud of degrading outputs) | BQ1: ann. p50 SLD degr, yr1-7> | BR1: =BS1/(BT1+BS1*(BB6+BH6)*0.5) -> -0.0084354824 | BS1: {=LINEST(BB4:BH4,BB6:BH6,TRUE,FALSE)} -> -0.0080109115 | BT1: 0.9817121 | BV1: p50 SLD degr, yr7-16> | BW1: =BX1/(BY1+BX1*(BH6+BQ6)*0.5) -> -0.044409205 | BX1: {=LINEST(BH4:BQ4,BH6:BQ6,TRUE,FALSE)} -> -0.035351983 | BY1: 1.2025986 | CA1: min PI | CB1: =MIN($CB$7:$CB$106) -> 0.34604067 | CC1: avg PI | CD1: =$CB$111 -> 0.83956393 | CF1: =CG1/(CH1+CG1*(16+1)/2) -> -0.026808155 | CG1: {=LINEST($BB$4:$BQ$4,$BB$6:$BQ$6)} -> -0.022941747 | CH1: 1.0507798 | CI1: SLD degr rate over 16 yrs for the median system | CO1: Cold: TMOD <40 °C | ED1: Full lifetime | EE1: Full lifetime | EF1: Full lifetime | EG1: Full lifetime | FR1: =MAX(FR7:FR106) -> 0.051
A2: data w/eqn. | B2: just data | C2: < data entry color key | N2: MWp | O2: =SUM(N$7:N$106) -> 639.94948 | Q2: Top100 calcs, wtd by energy | X2: avg> | Y2: =AVERAGE(Y7:Y106) -> 0.012448983 | Z2: =AVERAGE(Z7:Z106) -> 0.88237321 | AB2: w/o degr | AC2: w/degr | AD2: MWh-wtd PI | AF2: smallest | AG2: =MIN($N$7:$N$106) -> 0.2576 | AH2: MWp | AJ2: CA | AK2: =COUNTIF($K$7:$K$106,AJ2)/100 -> 0.3 | AL2: NC | AM2: =COUNTIF($K$7:$K$106,AL2)/100 -> 0.07 | AN2: FL | AO2: =COUNTIF($K$7:$K106,AN2)/100 -> 0.04 | AP2: MA | AQ2: =COUNTIF($K$7:$K$106,AP2)/100 -> 0.03 | AT2: %,PI,MWp | AU2: %,PI,MWp | AY2: ann. p90 expon degr, Yr1-Yr16 > | AZ2: =AX1-1 -> -0.068281556 | BA2: p90 | BB2: =BB3-1.28*BB5 -> 0.75089983 | BC2: =BC3-1.28*BC5 -> 0.69731657 | BD2: =BD3-1.28*BD5 -> 0.67702938 | BE2: =BE3-1.28*BE5 -> 0.69665631 | BF2: =BF3-1.28*BF5 -> 0.6757683 | BG2: =BG3-1.28*BG5 -> 0.6734932 | BH2: =BH3-1.28*BH5 -> 0.69872431 | BI2: =BI3-1.28*BI5 -> 0.57219694 | ... BR2: =BR3-1.28*BR5 -> 0.3027009 | BY2: =COUNTIF(BB7:BX106,1.15) -> 12 | CA2: median PI | CB2: =MEDIAN($CB$7:$CB$106) -> 0.86694533 | CC2: p90(1.28σ) | CD2: =CD1-1.28*$CB$112 -> 0.6601333 | CF2: =CG2/(CH2+CG2*(16+1)/2) -> -0.058999957 | CG2: {=LINEST($BB$113:$BQ$113,$BB$6:$BQ$6)} -> -0.033876166 | CH2: 0.86212014 | CI2: SLD degr rate over 16 yrs for the p90 system | CO2: Medium: 40 °C < TMOD < 50 °C | DG2: # at 2 yr | DH2: =COUNTIF($DD$7:$DD$106,2) -> 5 | ED2: # of systems | EE2: # of systems | EF2: # of systems | EG2: # of systems | EI2: 7-yr only | EJ2: 7-yr only | FQ2: Median | FR2: Median | FS2: Median | FV2: Median | FW2: Median
B3: Expected PR | C3: Fixed | D3: 0.8 | F3: Fleet median degradation, 1st 7 yrs | H3: =$BR$1 -> -0.0084354824 | J3: Expctd Degr | K3: 0.005 | N3: MW,ac | O3: =SUM(O$7:O$106) -> 543.706 | P3: =MEDIAN(P7:P106) -> 1980.5681 | Q3: =SUM(AB7:AX106) -> 13660673 | R3: MWh,act. | S3: =MEDIAN(S7:S106) -> 41.413315 | T3: < median Tmod | X3: median> | Y3: =MEDIAN(Y7:Y106) -> 0 | Z3: =MEDIAN(Z7:Z106) -> 1 | AB3: =SUM(AB7:AX106) -> 13660673 | AD3: =AB3/AB4 -> 0.88882234 | AF3: average | AG3: =AVERAGE($N$7:$N$106) -> 6.3994948 | AH3: MWp | AJ3: NJ | AK3: =COUNTIF($K$7:$K$106,AJ3)/100 -> 0.16 | AL3: PA | AM3: =COUNTIF($K$7:$K$106,AL3)/100 -> 0.06 | AN3: NM | AO3: =COUNTIF($K$7:$K106,AN3)/100 -> 0.04 | AP3: HI | AQ3: =COUNTIF($K$7:$K$106,AP3)/100 -> 0.02 | AT3: =COUNTIF($I$7:$I$106,"Tracker")/100 -> 0.34 | AU3: =COUNTIF($I$7:$I$106,"Fixed")/100 -> 0.66 | BA3: avg | BB3: =AVERAGE(BB$7:BB$106) -> 0.92771302 | BC3: =AVERAGE(BC$7:BC$106) -> 0.92596863 | BD3: =AVERAGE(BD$7:BD$106) -> 0.91478067 | BE3: =AVERAGE(BE$7:BE$106) -> 0.91661908 | BF3: =AVERAGE(BF$7:BF$106) -> 0.89899124 | BG3: =AVERAGE(BG$7:BG$106) -> 0.89643489 | BH3: =AVERAGE(BH$7:BH$106) -> 0.8843238 | BI3: =AVERAGE(BI$7:BI$106) -> 0.84734173 | ... BX3: =AVERAGE(BX$7:BX$106) -> 0.16281613 | CA3: max PI | CB3: =MAX($CB$7:$CB$106) -> 1.045153 | CC3: p90(rank) | CD3: =VLOOKUP(MATCH(90,$CC$7:$CC$106,0),$BY$7:$CB$106,4) -> 0.68447422 | CE3: =MEDIAN(CE7:CE106) -> -0.023304756 | CH3: =MAX(CH7:CH106) -> 1.0438358 | CO3: Hot: TMOD > 50 °C | DD3: =MODE($DD$7:$DD$106) -> 1 | DE3: Most common | DG3: # at 1 yr | DH3: =COUNTIF($DD$7:$DD$106,1) -> 68 | EA3: Median 7-yr PI | EB3: =MEDIAN(EB7:EB106) -> 0.93316367 | ED3: =COUNT(ED7:ED106) -> 12 | EE3: =COUNT(EE7:EE106) -> 12 | EF3: =COUNT(EF7:EF106) -> 47 | EG3: =COUNT(EG7:EG106) -> 47 | EI3: =COUNT(EI7:EI106) -> 12 | EJ3: =COUNT(EJ7:EJ106) -> 47 | EN3: median | EQ3: median | FQ3: =MEDIAN(FQ7:FQ106) -> 0.10423531 | FR3: =MEDIAN(FR7:FR106) -> 0.03 | FS3: =MEDIAN(FS7:FS106) -> 0.28957093 | FV3: =MEDIAN(FV7:FV106) -> 0.050538705 | FW3: =MEDIAN(FW7:FW106) -> 0.5948563
B4: (user input) | C4: Tracker | D4: 0.76 | F4: Fleet median degradation, last 9 yrs | H4: =$BW$1 -> -0.044409205 | J4: MedianPI> | K4: =$CB$2 -> 0.86694533 | L4: (unwghtd) | N4: ILR | O4: =O2/O3 -> 1.1770138 | P4: =STDEV(P7:P106)/P5 -> 0.22513168 | Q4: =SUM(BZ7:BZ106) -> 14873746 | R4: MWh,exp. | S4: =AVERAGE(S7:S106) -> 41.449578 | T4: <avg|Tmod|stdev> | U4: =STDEV(S7:S106) -> 6.4418167 | X4: =AVERAGE(X7:X106) -> 0.37189762 | Y4: CCC-based | Z4: estim. | AB4: =SUMPRODUCT(AA7:AA106,AY7:AY106) -> 15369408 | AC4: =$BZ$110 -> 14873746 | AD4: =AB3/AC4 -> 0.91844204 | AF4: largest | AG4: =MAX($N$7:$N$106) -> 60.5 | AH4: MWp | AJ4: CO | AK4: =COUNTIF($K$7:$K$106,AJ4)/100 -> 0.08 | AL4: AZ | AM4: =COUNTIF($K$7:$K$106,AL4)/100 -> 0.06 | AN4: NV | AO4: =COUNTIF($K$7:$K106,AN4)/100 -> 0.04 | AP4: TX | AQ4: =COUNTIF($K$7:$K$106,AP4)/100 -> 0.02 | AT4: =AVERAGEIF($CD$7:$CD$106,"Tracker",$CB$7:$CB$106) -> 0.83273937 | AU4: =AVERAGEIF($CD$7:$CD$106,"Fixed",$CB$7:$CB$106) -> 0.84307961 | AY4: ann. p50 expon degr, Yr1-Yr16 > | AZ4: =AZ1-1 -> -0.028167081 | BA4: p50 | BB4: =MEDIAN(BB$7:BB$106) -> 0.95554712 | BC4: =MEDIAN(BC$7:BC$106) -> 0.97496459 | BD4: =MEDIAN(BD$7:BD$106) -> 0.96635514 | BE4: =MEDIAN(BE$7:BE$106) -> 0.95478358 | BF4: =MEDIAN(BF$7:BF$106) -> 0.94922573 | BG4: =MEDIAN(BG$7:BG$106) -> 0.93101463 | BH4: =MEDIAN(BH$7:BH$106) -> 0.91578839 | BI4: =MEDIAN(BI$7:BI$106) -> 0.90286708 | ... BX4: =MEDIAN(BX$7:BX$106) -> 0.16281613 | BZ4: Lifetime expected energy over number of years reported in the EIA database | CH4: =MIN(CH7:CH106) -> 0.94582881 | CO4: Temp. Zone (>50,>40,<40) | CT4: System Size Differentiator | CY4: Ownership Differentiator | DB4: average> | DC4: =AVERAGE(DC7:DC106) -> 1.1634732 | DD4: Delay Differentiator: years between start-up & full ops | DJ4: Developer Differentiator | DP4: Module type differentiator | EA4: Std dev of 7-yr PI | EB4: =STDEV(EB7:EB106) -> 0.11293641 | ED4: Median PI | EE4: Median Degr | EF4: Median PI | EG4: Median Degr | EI4: Median PI | EJ4: Median PI | EN4: =MEDIAN(EN7:EN106) -> -0.011206468 | EQ4: =MEDIAN(EQ7:EQ106) -> -0.030461872 | ES4: Inter-annual variability (IAV) analysis of generation and insolation (to the right) | FR4: Avg
D5: =MODE(D7:D106) -> 2011 | E5: =COUNTIF(D7:D106,D5) -> 34 | J5: 1st 7yrs PI> | K5: =$EB$3 -> 0.93316367 | L5: (unwghtd) | N5: =MEDIAN(N7:N106) -> 2.2 | P5: =AVERAGE(P7:P106) -> 2071.9342 | Q5: =Q3/Q4 -> 0.91844204 | R5: < Fleet PI, wtd. | S5: Pvsyst,10city correlation by Tim from 2004 | T5: H>50, M>40, | X5: =MEDIAN(X7:X106) -> 0.36578658 | Y5: Corr'n. | Z5: Visible | AB5: Reported raw MWh per year - a small percentage, roughly 1%, of these numbers are impossibly high and will be capped at no greater than a 1.15 PI on the derived table to the right | AT5: =AVERAGEIF($CD$7:$CD$106,"Tracker",$N$7:$N$106) -> 6.7108853 | AU5: =AVERAGEIF($CD$7:$CD$106,"Fixed",$N$7:$N$106) -> 6.2390816 | AY5: Median age | AZ5: Lifetime | BA5: stdev | BB5: =STDEV(BB$7:BB$106) -> 0.1381353 | BC5: =STDEV(BC$7:BC$106) -> 0.17863442 | BD5: =STDEV(BD$7:BD$106) -> 0.1857432 | BE5: =STDEV(BE$7:BE$106) -> 0.17184592 | BF5: =STDEV(BF$7:BF$106) -> 0.17439292 | BG5: =STDEV(BG$7:BG$106) -> 0.1741732 | BH5: =STDEV(BH$7:BH$106) -> 0.1449996 | BI5: =STDEV(BI$7:BI$106) -> 0.21495687 | ... BR5: =STDEV(BR$7:BR$106) -> 0.31023098 | BZ5: This term uses the economics formula F/A, uniform series compound amount factor | CH5: Tm expec. | CI5: Average PI and degradation by state | CO5: Average PI and SLD degr by temperature | CY5: CHP=Combined Heat & Power | DB5: median> | DC5: =MEDIAN(DC7:DC31) -> 1.125 | DD5: =AVERAGE($DD$7:$DD$106) -> 0.96 | DE5: =AVERAGE(DE7:DE106) -> 15.41 | DF5: =MIN($DD$7:$DD$106) -> 0 | DG5: <-min,#-> | DH5: =COUNTIF($DD$7:$DD$106,$DF$5) -> 21 | DP5: (First Solar was sometimes used by | DT5: Actual | DU5: Expected | DV5: Expected | DW5: Expected | DX5: Expected | DY5: Expected | DZ5: Expected | EA5: Expected | EB5: 7-year | ED5: =MEDIAN(ED7:ED106) -> 0.74187241 | EE5: =MEDIAN(EE7:EE106) -> -0.055655574 | EF5: =MEDIAN(EF7:EF106) -> 0.86925867 | EG5: =MEDIAN(EG7:EG106) -> -0.017194623 | EI5: =MEDIAN(EI7:EI106) -> 0.89926888 | EJ5: =MEDIAN(EJ7:EJ106) -> 0.92412486 | EL5: First 7 years: linear degr. | EN5: 7-yr | EO5: Subsequent years: linear degr. | EQ5: post-7 | ES5: Squared deviation from straight-line fit, by year | FR5: =AVERAGE(FR7:FR106) -> 0.03138 | FS5: =COUNTIF($FS$7:$FS$106,">0.8") -> 12 | FT5: count | FV5: RMS var.
A6: Line# | B6: EIA# | C6: Name | D6: 1st full yr | E6: 1st kWh | F6: Sector | G6: Module type | H6: Developer | I6: (F)ix,(T)rkr | J6: Slope/Tilt | K6: State | L6: Lat | M6: Long | N6: MWp | O6: MWac | P6: POA (by eqn.) | Q6: TMY2 Source | R6: Annual T,air | S6: Estim. Tmod | T6: and C<40 | U6: GHI | V6: DHI | W6: Kt | X6: DF | Y6: Est.Clip | Z6: Degr Frac. | AA6: p50,Yr1 MWh | AB6: 1 | AC6: =AB6+1 -> 2 | AD6: =AC6+1 -> 3 | AE6: =AD6+1 -> 4 | AF6: =AE6+1 -> 5 | AG6: =AF6+1 -> 6 | AH6: =AG6+1 -> 7 | AI6: =AH6+1 -> 8 | AJ6: =AI6+1 -> 9 | ... AX6: =AW6+1 -> 23 | AY6: =MEDIAN($AY$7:$AY$106) -> 14 | AZ6: PR | BA6: Line # | BB6: =AB6 -> 1 | BC6: =AC6 -> 2 | BD6: =AD6 -> 3 | BE6: =AE6 -> 4 | BF6: =AF6 -> 5 | BG6: =AG6 -> 6 | BH6: =AH6 -> 7 | BI6: =AI6 -> 8 | ... BX6: =AX6 -> 23 | BY6: =BA6 -> Line # | BZ6: Expected | CA6: Actual | CB6: Lifetime PI | CC6: Percentile Rank | CD6: Type | CE6: Lifetime Degr | CF6: Linest slope | CG6: Linest Int. | CH6: PR adj. | CI6: State | CJ6: # systems | CK6: PI | CL6: Degr | CN6: Bin % | CO6: Type | CP6: # systems | CQ6: PI | CR6: SLD Degr | CT6: Size | CU6: PI | CV6: SLD | CW6: % of systems | CY6: Type | CZ6: PI | DA6: SLD | DB6: # systems | DC6: ILR | DD6: =STDEV($DD$7:$DD$106) -> 0.70953107 | DE6: field age | DF6: =MAX($DD$7:$DD$106) -> 3 | DG6: <-max,#-> | DH6: =COUNTIF($DD$7:$DD$106,$DF$6) -> 6 | DJ6: Name | DK6: Number | DL6: MWp | DM6: Avg PI | DN6: Avg SLD | DP6: developers other than FS) | DT6: 7-year MWh | DU6: yr 1 MWh | DV6: yr 2 MWh | DW6: yr 3 MWh | DX6: yr 4 MWh | DY6: yr 5 MWh | DZ6: yr 6 MWh | EA6: yr 7 MWh | EB6: PI | ED6: Hot | EE6: Hot | EF6: Cold | EG6: Cold | EI6: Hot | EJ6: Cold | EL6: slope | EM6: intercept | EN6: degr. | EO6: slope | EP6: intercept | EQ6: degr | ES6: 1 | ET6: =ES6+1 -> 2 | EU6: =ET6+1 -> 3 | EV6: =EU6+1 -> 4 | EW6: =EV6+1 -> 5 | EX6: =EW6+1 -> 6 | EY6: =EX6+1 -> 7 | EZ6: =EY6+1 -> 8 | FA6: =EZ6+1 -> 9 | ... FO6: =FN6+1 -> 23 | FQ6: RMS variability | FR6: TMY2 variability | FS6: % explained variability | FV6: 1st 7 yrs | FW6: % explained | FY6: Age | FZ6: Number | GA6: Fixed-tilt | GB6: Tracking
A7: 1 | B7: 141 | C7: Agua Fria PV-3 | D7: 2003 | E7: 2003 | F7: Electric Utility | G7: c-Si | H7: Other utility | I7: Tracker | J7: 0 | K7: AZ | L7: 33.5567 | M7: -112.21534 | N7: =2240*(115/1000000) -> 0.2576 | O7: 0.25 | P7: =365.25*8 -> 2922 | Q7: Phoenix | R7: 22.6 | S7: =R7+11.448+2.715*IF($I7="Tracker",P7*0.95,P7)/365.25 -> 54.682 | T7: =IF(S7>=50,"H",IF(S7>=40,"M","C")) -> H | U7: 2117 | V7: 566 | W7: 0.678 | X7: =V7/U7 -> 0.26735947 | Y7: =MAX(0,IF($I7="Tracker",P7*0.95,P7)*(N7/O7)*0.0000994+0.3284*X7-0.358) -> 0.014113414 | Z7: =EXP(-12.9*Y7) -> 0.83354879 | AA7: =N7*P7*INDEX($C$3:$D$4,MATCH(I7,$C$3:$C$4,0),2)*CH7 -> 541.77865 | AB7: 395 | AC7: 297 | AD7: 111 | AE7: 285 | AF7: 398 | AG7: 437 | AH7: 201 | AI7: 438 | AJ7: 447 | AK7: 437 | AL7: 395 | AM7: 255 | AN7: 0 | AO7: 153 | AP7: 217 | AQ7: 281 | AR7: 136 | AS7: 0 | AT7: 0 | AU7: 0 | AV7: 0 | AW7: 21 | AX7: 79 | AY7: 23 | AZ7: =SUM(AB7:AX7)/AY7/N7/P7 -> 0.28783061 | BA7: =A7 -> 1 | BB7: =IF(ISNUMBER(AB7),MIN(1.15,AB7/($AA7*(1-$K$3)^(BB$6-1))),"") -> 0.72908004 | BC7: =IF(ISNUMBER(AC7),MIN(1.15,AC7/($AA7*(1-$K$3)^(BC$6-1))),"") -> 0.55094911 | BD7: =IF(ISNUMBER(AD7),MIN(1.15,AD7/($AA7*(1-$K$3)^(BD$6-1))),"") -> 0.206945 | BE7: =IF(ISNUMBER(AE7),MIN(1.15,AE7/($AA7*(1-$K$3)^(BE$6-1))),"") -> 0.53401534 | BF7: =IF(ISNUMBER(AF7),MIN(1.15,AF7/($AA7*(1-$K$3)^(BF$6-1))),"") -> 0.74949521 | BG7: =IF(ISNUMBER(AG7),MIN(1.15,AG7/($AA7*(1-$K$3)^(BG$6-1))),"") -> 0.82707358 | BH7: =IF(ISNUMBER(AH7),MIN(1.15,AH7/($AA7*(1-$K$3)^(BH$6-1))),"") -> 0.38232763 | BI7: =IF(ISNUMBER(AI7),MIN(1.15,AI7/($AA7*(1-$K$3)^(BI$6-1))),"") -> 0.83731845 | ... BX7: =IF(ISNUMBER(AX7),MIN(1.15,AX7/($AA7*(1-$K$3)^(BX$6-1))),"") -> 0.16281613 | BY7: =A7 -> 1 | BZ7: =$AA7*IF($K$3=0,$AY7,((1-$K$3)^$AY7-1)/-$K$3) -> 11798.958 | CA7: =SUM(AB7:AX7) -> 4983 | CB7: =CA7/BZ7 -> 0.42232544 | CC7: =ROUND(RANK(CB7,$CB$7:$CB$106,0),0) -> 99 | CD7: =I7 -> Tracker | CE7: =CF7/(CG7+CF7*AY7/2) -> -0.076876016 | CF7: {=LINEST(AB7:AX7,AB$6:AX$6,TRUE,FALSE)} -> -17.321146 | CG7: 424.50593 | CH7: =1+IF(G7="CdSCdTe",-0.0025,-0.004)*(S7-$S$4) -> 0.94707031 | CI7: CA | CJ7: =COUNTIF($K$7:$K$106,$CI7) -> 30 | CK7: =AVERAGEIF($K$7:$K$106,$CI7,$CB$7:$CB$106) -> 0.80976998 | CL7: =AVERAGEIF($K$7:$K$106,$CI7,$CE$7:$CE$106) -> -0.045529532 | CN7: =CP7/$CP$10 -> 0.12 | CO7: H | CP7: =COUNTIF($T$7:$T$106,$CO7) -> 12 | CQ7: =AVERAGEIFS($CB$7:$CB$106,$T$7:$T$106,$CO7) -> 0.74933481 | CR7: =AVERAGEIFS($CE$7:$CE$106,$T$7:$T$106,$CO7) -> -0.053836658 | CT7: >5 MW,ac | CU7: =AVERAGEIFS($CB$7:$CB$106,$O$7:$O$106,">5") -> 0.94484909 | CV7: =AVERAGEIFS($CE$7:$CE$106,$O$7:$O$106,">5") -> -0.02042797 | CW7: =COUNTIF($O$7:$O$106,">5") -> 23 | CY7: Commercial CHP | CZ7: =AVERAGEIF($F$7:$F$106,$CY7,$CB$7:$CB$106) -> 0.71747425 | DA7: =AVERAGEIF($F$7:$F$106,$CY7,$CE$7:$CE$106) -> -0.012305416 | DB7: =COUNTIF($F$7:$F$106,$CY7) -> 2 | DC7: =N7/O7 -> 1.0304 | DD7: =D7-E7 -> 0 | DE7: =AY7+DD7 -> 23 | DJ7: BlueOak | DK7: =COUNTIF($H$7:$H$106,$DJ7) -> 1 | DL7: =SUMIF($H$7:$H$106,$DJ7,$N$7:$N$106) -> 37.7 | DM7: =AVERAGEIF($H$7:$H$106,$DJ7,$CB$7:$CB$106) -> 1.025617 | DN7: =AVERAGEIF($H$7:$H$106,$DJ7,$CE$7:$CE$106) -> -0.010895507 | DP7: CdSCdTe | DQ7: =COUNTIF($G$7:$G$106,$DP7) -> 15 | DT7: =SUM(AB7:AH7) -> 2124 | DU7: =IF(BB7>0,AB7/BB7,$AA7) -> 541.77865 | DV7: =IF(BC7>0,AC7/BC7,$AA7) -> 539.06976 | DW7: =IF(BD7>0,AD7/BD7,$AA7) -> 536.37441 | DX7: =IF(BE7>0,AE7/BE7,$AA7) -> 533.69253 | DY7: =IF(BF7>0,AF7/BF7,$AA7) -> 531.02407 | DZ7: =IF(BG7>0,AG7/BG7,$AA7) -> 528.36895 | EA7: =IF(BH7>0,AH7/BH7,$AA7) -> 525.72711 | EB7: =DT7/SUM(DU7:EA7) -> 0.56851709 | ED7: =IF($T7="H",CB7," ") -> 0.42232544 | EE7: =IF($T7="H",$CE7," ") -> -0.076876016 | EF7: =IF($T7="C",CB7," ") | EG7: =IF($T7="C",CE7," ") | EI7: =IF($T7="H",$EB7," ") -> 0.56851709 | EJ7: =IF($T7="C",$EB7," ") | EL7: {=LINEST($AB7:$AH7,$AB$6:$AH$6,TRUE,FALSE)} -> -0.53571429 | EM7: 305.57143 | EN7: =EL7/(EL7*($AB$6+$AH$6)*0.5+EM7) -> -0.0017655367 | EO7: {=LINEST($AH7:$AX7,$AH$6:$AX$6,TRUE,FALSE)} -> -26.242647 | EP7: 573.63971 | EQ7: =EO7/(EO7*(AY7/2+7/2)+EP7) -> -0.14579248 | ES7: =($EM7+$EL7*ES$6-AB7)^2 -> 8093.5727 | ET7: =($EM7+$EL7*ET$6-AC7)^2 -> 56.25 | EU7: =($EM7+$EL7*EU$6-AD7)^2 -> 37235.216 | EV7: =($EM7+$EL7*EV$6-AE7)^2 -> 339.61224 | EW7: =($EM7+$EL7*EW$6-AF7)^2 -> 9045.3686 | EX7: =($EM7+$EL7*EX$6-AG7)^2 -> 18128.699 | EY7: =($EM7+$EL7*EY$6-AH7)^2 -> 10164.96 | EZ7: =($EP7+$EO7*EZ$6-AI7)^2 -> 5520.7085 | FA7: =($EP7+$EO7*FA$6-AJ7)^2 -> 11999.914 | FB7: =($EP7+$EO7*FB$6-AK7)^2 -> 15822.31 | FC7: =($EP7+$EO7*FC$6-AL7)^2 -> 12106.471 | FD7: =($EP7+$EO7*FD$6-AM7)^2 -> 13.897545 | FE7: =($EP7+$EO7*FE$6-AN7)^2 -> 54049.412 | FF7: =($EP7+$EO7*FF$6-AO7)^2 -> 2834.7795 | FG7: =($EP7+$EO7*FG$6-AP7)^2 -> 1369 | ... FO7: =($EP7+$EO7*FO$6-AX7)^2 -> 11868.18 | FQ7: =SQRT(AVERAGE(ES7:FO7))/AVERAGE(AB7:AX7) -> 0.46585894 | FR7: 0.036 | FS7: =FR7/FQ7 -> 0.07727661 | FV7: =SQRT(AVERAGE(ES7:EY7))/AVERAGE(AB7:AH7) -> 0.35900466 | FW7: =FR7/FV7 -> 0.10027725 | FY7: 12 | FZ7: =COUNTIF($AY$7:$AY$106,FY7) -> 3 | GA7: =COUNTIFS($I$7:$I$106,"Fixed",$AY$7:$AY$106,$FY7) -> 3 | GB7: =COUNTIFS($I$7:$I$106,"Tracker",$AY$7:$AY$106,$FY7) -> 0
A8: =A7+1 -> 2 | B8: 56568 | C8: Nellis Sunpower | D8: 2008 | E8: 2007 | F8: Commercial Non-CHP | G8: Si_IBC | H8: SunPower | I8: Tracker | J8: 20 | K8: NV | L8: 36.26 | M8: -115.05 | N8: 14.2 | O8: 13.2 | P8: =365.25*(8.7*(12.2/$N$8)+8.1*(2/$N$8)) -> 3146.8088 | Q8: Las Vegas | R8: 19.5 | S8: =R8+11.448+2.715*IF($I8="Tracker",P8*0.95,P8)/365.25 -> 53.16951 | T8: =IF(S8>=50,"H",IF(S8>=40,"M","C")) -> H | U8: 2078 | V8: 550 | W8: 0.684 | X8: =V8/U8 -> 0.26467757 | Y8: =MAX(0,IF($I8="Tracker",P8*0.95,P8)*(N8/O8)*0.0000994+0.3284*X8-0.358) -> 0.048584873 | Z8: =EXP(-12.9*Y8) -> 0.53432828 | AA8: 32000 | AB8: 32500 | AC8: 32000 | AD8: 31301 | AE8: 32125 | AF8: 32159 | AG8: 31758 | AH8: 31202 | AI8: 30428 | AJ8: 19725 | AK8: 28213 | AL8: 26910 | AM8: 26474 | AN8: 24959 | AO8: 19180 | AP8: 19975 | AQ8: 21723 | AR8: 23764 | AY8: 17 | AZ8: =SUM(AB8:AX8)/AY8/N8/P8 -> 0.61133723 | BA8: =A8 -> 2 | BB8: =IF(ISNUMBER(AB8),MIN(1.15,AB8/($AA8*(1-$K$3)^(BB$6-1))),"") -> 1.015625 | BC8: =IF(ISNUMBER(AC8),MIN(1.15,AC8/($AA8*(1-$K$3)^(BC$6-1))),"") -> 1.0050251 | BD8: =IF(ISNUMBER(AD8),MIN(1.15,AD8/($AA8*(1-$K$3)^(BD$6-1))),"") -> 0.98801167 | BE8: =IF(ISNUMBER(AE8),MIN(1.15,AE8/($AA8*(1-$K$3)^(BE$6-1))),"") -> 1.0191167 | BF8: =IF(ISNUMBER(AF8),MIN(1.15,AF8/($AA8*(1-$K$3)^(BF$6-1))),"") -> 1.0253219 | BG8: =IF(ISNUMBER(AG8),MIN(1.15,AG8/($AA8*(1-$K$3)^(BG$6-1))),"") -> 1.017625 | BH8: =IF(ISNUMBER(AH8),MIN(1.15,AH8/($AA8*(1-$K$3)^(BH$6-1))),"") -> 1.0048332 | BI8: =IF(ISNUMBER(AI8),MIN(1.15,AI8/($AA8*(1-$K$3)^(BI$6-1))),"") -> 0.98483135 | ... BR8: =IF(ISNUMBER(AR8),MIN(1.15,AR8/($AA8*(1-$K$3)^(BR$6-1))),"") -> 0.80463751 | BY8: =A8 -> 2 | BZ8: =$AA8*IF($K$3=0,$AY8,((1-$K$3)^$AY8-1)/-$K$3) -> 522774.6 | CA8: =SUM(AB8:AX8) -> 464396 | CB8: =CA8/BZ8 -> 0.88832931 | CC8: =ROUND(RANK(CB8,$CB$7:$CB$106,0),0) -> 43 | CD8: =I8 -> Tracker | CE8: =CF8/(CG8+CF8*AY8/2) -> -0.029172847 | CF8: {=LINEST(AB8:AR8,AB$6:AR$6,TRUE,FALSE)} -> -808.72304 | CG8: 34595.919 | CH8: =1+IF(G8="CdSCdTe",-0.0025,-0.004)*(S8-$S$4) -> 0.95312027 | CI8: NJ | CJ8: =COUNTIF($K$7:$K$106,$CI8) -> 16 | CK8: =AVERAGEIF($K$7:$K$106,$CI8,$CB$7:$CB$106) -> 0.86867304 | CL8: =AVERAGEIF($K$7:$K$106,$CI8,$CE$7:$CE$106) -> -0.017528923 | CN8: =CP8/$CP$10 -> 0.41 | CO8: M | CP8: =COUNTIF($T$7:$T$106,$CO8) -> 41 | CQ8: =AVERAGEIFS($CB$7:$CB$106,$T$7:$T$106,$CO8) -> 0.84330881 | CR8: =AVERAGEIFS($CE$7:$CE$106,$T$7:$T$106,$CO8) -> -0.03588841 | CT8: <5 MW,ac | CU8: =AVERAGEIFS($CB$7:$CB$106,$O$7:$O$106,"<=5") -> 0.80811512 | CV8: =AVERAGEIFS($CE$7:$CE$106,$O$7:$O$106,"<=5") -> -0.034297443 | CW8: =COUNTIF($O$7:$O$106,"<=5") -> 77 | CY8: Commercial Non-CHP | CZ8: =AVERAGEIF($F$7:$F$106,$CY8,$CB$7:$CB$106) -> 0.76961345 | DA8: =AVERAGEIF($F$7:$F$106,$CY8,$CE$7:$CE$106) -> -0.062955953 | DB8: =COUNTIF($F$7:$F$106,$CY8) -> 9 | DC8: =N8/O8 -> 1.0757576 | DD8: =D8-E8 -> 1 | DE8: =AY8+DD8 -> 18 | DJ8: Conergy | DK8: =COUNTIF($H$7:$H$106,$DJ8) -> 1 | DL8: =SUMIF($H$7:$H$106,$DJ8,$N$7:$N$106) -> 1.5936 | DM8: =AVERAGEIF($H$7:$H$106,$DJ8,$CB$7:$CB$106) -> 0.90564218 | DN8: =AVERAGEIF($H$7:$H$106,$DJ8,$CE$7:$CE$106) -> -0.031310529 | DP8: c-Si | DQ8: =COUNTIF($G$7:$G$106,$DP8) -> 80 | DT8: =SUM(AB8:AH8) -> 223045 | DU8: =IF(BB8>0,AB8/BB8,$AA8) -> 32000 | DV8: =IF(BC8>0,AC8/BC8,$AA8) -> 31840 | DW8: =IF(BD8>0,AD8/BD8,$AA8) -> 31680.8 | DX8: =IF(BE8>0,AE8/BE8,$AA8) -> 31522.396 | DY8: =IF(BF8>0,AF8/BF8,$AA8) -> 31364.784 | DZ8: =IF(BG8>0,AG8/BG8,$AA8) -> 31207.96 | EA8: =IF(BH8>0,AH8/BH8,$AA8) -> 31051.92 | EB8: =DT8/SUM(DU8:EA8) -> 1.0107725 | ED8: =IF($T8="H",CB8," ") -> 0.88832931 | EE8: =IF($T8="H",$CE8," ") -> -0.029172847 | EF8: =IF($T8="C",CB8," ") | EG8: =IF($T8="C",CE8," ") | EI8: =IF($T8="H",$EB8," ") -> 1.0107725 | EJ8: =IF($T8="C",$EB8," ") | EL8: {=LINEST($AB8:$AH8,$AB$6:$AH$6,TRUE,FALSE)} -> -125.71429 | EM8: 32366.429 | EN8: =EL8/(EL8*($AB$6+$AH$6)*0.5+EM8) -> -0.0039453922 | EO8: {=LINEST($AH8:$AR8,$AH$6:$AR$6,TRUE,FALSE)} -> -829.79091 | EP8: 34735.036 | EQ8: =EO8/(EO8*(AY8/2+7/2)+EP8) -> -0.033489633 | ES8: =($EM8+$EL8*ES$6-AB8)^2 -> 67229.082 | ET8: =($EM8+$EL8*ET$6-AC8)^2 -> 13225 | EU8: =($EM8+$EL8*EU$6-AD8)^2 -> 473737.22 | EV8: =($EM8+$EL8*EV$6-AE8)^2 -> 68344.898 | EW8: =($EM8+$EL8*EW$6-AF8)^2 -> 177361.31 | EX8: =($EM8+$EL8*EX$6-AG8)^2 -> 21274.306 | EY8: =($EM8+$EL8*EY$6-AH8)^2 -> 80899.612 | EZ8: =($EP8+$EO8*EZ$6-AI8)^2 -> 5434917.3 | FA8: =($EP8+$EO8*FA$6-AJ8)^2 -> 56880530 | FB8: =($EP8+$EO8*FB$6-AK8)^2 -> 3153723.9 | FC8: =($EP8+$EO8*FC$6-AL8)^2 -> 1696932.5 | FD8: =($EP8+$EO8*FD$6-AM8)^2 -> 2877958 | FE8: =($EP8+$EO8*FE$6-AN8)^2 -> 1022617.4 | FF8: =($EP8+$EO8*FF$6-AO8)^2 -> 15507558 | FG8: =($EP8+$EO8*FG$6-AP8)^2 -> 5350768.1 | ... FI8: =($EP8+$EO8*FI$6-AR8)^2 -> 9830790.2 | FQ8: =SQRT(AVERAGE(ES8:FI8))/AVERAGE(AB8:AR8) -> 0.089987083 | FR8: 0.041 | FS8: =FR8/FQ8 -> 0.45562095 | FV8: =SQRT(AVERAGE(ES8:EY8))/AVERAGE(AB8:AH8) -> 0.011266188 | FW8: =FR8/FV8 -> 3.6392079 | FY8: =FY7+1 -> 13 | FZ8: =COUNTIF($AY$7:$AY$106,FY8) -> 24 | GA8: =COUNTIFS($I$7:$I$106,"Fixed",$AY$7:$AY$106,$FY8) -> 14 | GB8: =COUNTIFS($I$7:$I$106,"Tracker",$AY$7:$AY$106,$FY8) -> 10
A9: =A8+1 -> 3 | B9: 56481 | C9: SunE Alamosa1 | D9: 2008 | E9: 2007 | F9: IPP Non-CHP | G9: c-Si | H9: SunEdison | I9: Tracker | J9: 0 | K9: CO | L9: 37.6903 | M9: -105.8805 | N9: 9.2 | O9: 8.2 | P9: =365.25*(8.8*(1/$N$9)+7.7*(8.2/$N$9)) -> 2856.0962 | Q9: Alamosa | R9: 5.1 | S9: =R9+11.448+2.715*IF($I9="Tracker",P9*0.95,P9)/365.25 -> 36.716614 | T9: =IF(S9>=50,"H",IF(S9>=40,"M","C")) -> C | U9: 1926 | V9: 518 | W9: 0.644 | X9: =V9/U9 -> 0.26895119 | Y9: =MAX(0,IF($I9="Tracker",P9*0.95,P9)*(N9/O9)*0.0000994+0.3284*X9-0.358) -> 0.032915122 | Z9: =EXP(-12.9*Y9) -> 0.65402803 | AA9: =N9*P9*INDEX($C$3:$D$4,MATCH(I9,$C$3:$C$4,0),2)*CH9 -> 20347.89 | AB9: 17531 | AC9: 17455 | AD9: 17608 | AE9: 17797 | AF9: 17573 | AG9: 16907 | AH9: 16601 | AI9: 2638 | AJ9: 2636 | AK9: 34876 | AL9: 15939 | AM9: 15517 | AN9: 14258 | AO9: 12321 | AP9: 13729 | AQ9: 11357 | AR9: 13435 | AY9: 17 | AZ9: =SUM(AB9:AX9)/AY9/N9/P9 -> 0.5779758 | BA9: =A9 -> 3 | BB9: =IF(ISNUMBER(AB9),MIN(1.15,AB9/($AA9*(1-$K$3)^(BB$6-1))),"") -> 0.86156351 | BC9: =IF(ISNUMBER(AC9),MIN(1.15,AC9/($AA9*(1-$K$3)^(BC$6-1))),"") -> 0.86213918 | BD9: =IF(ISNUMBER(AD9),MIN(1.15,AD9/($AA9*(1-$K$3)^(BD$6-1))),"") -> 0.8740665 | BE9: =IF(ISNUMBER(AE9),MIN(1.15,AE9/($AA9*(1-$K$3)^(BE$6-1))),"") -> 0.88788796 | BF9: =IF(ISNUMBER(AF9),MIN(1.15,AF9/($AA9*(1-$K$3)^(BF$6-1))),"") -> 0.88111825 | BG9: =IF(ISNUMBER(AG9),MIN(1.15,AG9/($AA9*(1-$K$3)^(BG$6-1))),"") -> 0.85198463 | BH9: =IF(ISNUMBER(AH9),MIN(1.15,AH9/($AA9*(1-$K$3)^(BH$6-1))),"") -> 0.84076839 | BI9: =IF(ISNUMBER(AI9),MIN(1.15,AI9/($AA9*(1-$K$3)^(BI$6-1))),"") -> 0.13427459 | ... BR9: =IF(ISNUMBER(AR9),MIN(1.15,AR9/($AA9*(1-$K$3)^(BR$6-1))),"") -> 0.71540009 | BY9: =A9 -> 3 | BZ9: =$AA9*IF($K$3=0,$AY9,((1-$K$3)^$AY9-1)/-$K$3) -> 332417.51 | CA9: =SUM(AB9:AX9) -> 258178 | CB9: =CA9/BZ9 -> 0.77666787 | CC9: =ROUND(RANK(CB9,$CB$7:$CB$106,0),0) -> 72 | CD9: =I9 -> Tracker | CE9: =CF9/(CG9+CF9*AY9/2) -> -0.018012393 | CF9: {=LINEST(AB9:AR9,AB$6:AR$6,TRUE,FALSE)} -> -276.03922 | CG9: 17671.294 | CH9: =1+IF(G9="CdSCdTe",-0.0025,-0.004)*(S9-$S$4) -> 1.0189319 | CI9: CO | CJ9: =COUNTIF($K$7:$K$106,$CI9) -> 8 | CK9: =AVERAGEIF($K$7:$K$106,$CI9,$CB$7:$CB$106) -> 0.82407751 | CL9: =AVERAGEIF($K$7:$K$106,$CI9,$CE$7:$CE$106) -> -0.024628205 | CN9: =CP9/$CP$10 -> 0.47 | CO9: C | CP9: =COUNTIF($T$7:$T$106,$CO9) -> 47 | CQ9: =AVERAGEIFS($CB$7:$CB$106,$T$7:$T$106,$CO9) -> 0.85933434 | CR9: =AVERAGEIFS($CE$7:$CE$106,$T$7:$T$106,$CO9) -> -0.021133653 | CT9: All | CU9: =AVERAGE($CB$7:$CB$106) -> 0.83956393 | CV9: =AVERAGE($CE$7:$CE$106) -> -0.031107464 | CW9: =SUM(CW7:CW8) -> 100 | CY9: All Commercial | CZ9: =SUMPRODUCT(CZ7:CZ8,$DB7:$DB8)/$DB9 -> 0.76013359 | DA9: =SUMPRODUCT(DA7:DA8,$DB7:$DB8)/$DB9 -> -0.053746765 | DB9: =SUM(DB7:DB8) -> 11 | DC9: =N9/O9 -> 1.1219512 | DD9: =D9-E9 -> 1 | DE9: =AY9+DD9 -> 18 | DJ9: Duke | DK9: =COUNTIF($H$7:$H$106,$DJ9) -> 4 | DL9: =SUMIF($H$7:$H$106,$DJ9,$N$7:$N$106) -> 5.935 | DM9: =AVERAGEIF($H$7:$H$106,$DJ9,$CB$7:$CB$106) -> 0.80917875 | DN9: =AVERAGEIF($H$7:$H$106,$DJ9,$CE$7:$CE$106) -> -0.044119046 | DP9: HIT | DQ9: =COUNTIF($G$7:$G$106,$DP9) -> 0 | DT9: =SUM(AB9:AH9) -> 121472 | DU9: =IF(BB9>0,AB9/BB9,$AA9) -> 20347.89 | DV9: =IF(BC9>0,AC9/BC9,$AA9) -> 20246.151 | DW9: =IF(BD9>0,AD9/BD9,$AA9) -> 20144.92 | DX9: =IF(BE9>0,AE9/BE9,$AA9) -> 20044.196 | DY9: =IF(BF9>0,AF9/BF9,$AA9) -> 19943.975 | DZ9: =IF(BG9>0,AG9/BG9,$AA9) -> 19844.255 | EA9: =IF(BH9>0,AH9/BH9,$AA9) -> 19745.034 | EB9: =DT9/SUM(DU9:EA9) -> 0.86570053 | ED9: =IF($T9="H",CB9," ") | EE9: =IF($T9="H",$CE9," ") | EF9: =IF($T9="C",CB9," ") -> 0.77666787 | EG9: =IF($T9="C",CE9," ") -> -0.018012393 | EI9: =IF($T9="H",$EB9," ") | EJ9: =IF($T9="C",$EB9," ") -> 0.86570053 | EL9: {=LINEST($AB9:$AH9,$AB$6:$AH$6,TRUE,FALSE)} -> -140.03571 | EM9: 17913.286 | EN9: =EL9/(EL9*($AB$6+$AH$6)*0.5+EM9) -> -0.0080697609 | EO9: {=LINEST($AH9:$AR9,$AH$6:$AR$6,TRUE,FALSE)} -> 50.309091 | EP9: 13333.291 | EQ9: =EO9/(EO9*(AY9/2+7/2)+EP9) -> 0.0036097504 | ES9: =($EM9+$EL9*ES$6-AB9)^2 -> 58685.063 | ET9: =($EM9+$EL9*ET$6-AC9)^2 -> 31760.332 | EU9: =($EM9+$EL9*EU$6-AD9)^2 -> 13183.96 | EV9: =($EM9+$EL9*EV$6-AE9)^2 -> 197009.16 | EW9: =($EM9+$EL9*EW$6-AF9)^2 -> 129522.87 | EX9: =($EM9+$EL9*EX$6-AG9)^2 -> 27579.719 | EY9: =($EM9+$EL9*EY$6-AH9)^2 -> 110247.72 | EZ9: =($EP9+$EO9*EZ$6-AI9)^2 -> 1.2316036e+08 | FA9: =($EP9+$EO9*FA$6-AJ9)^2 -> 1.2432412e+08 | FB9: =($EP9+$EO9*FB$6-AK9)^2 -> 4.4266553e+08 | FC9: =($EP9+$EO9*FC$6-AL9)^2 -> 4211972.6 | FD9: =($EP9+$EO9*FD$6-AM9)^2 -> 2496400 | FE9: =($EP9+$EO9*FE$6-AN9)^2 -> 73273.568 | FF9: =($EP9+$EO9*FF$6-AO9)^2 -> 2946778 | FG9: =($EP9+$EO9*FG$6-AP9)^2 -> 128828.79 | ... FI9: =($EP9+$EO9*FI$6-AR9)^2 -> 567830.75 | FQ9: =SQRT(AVERAGE(ES9:FI9))/AVERAGE(AB9:AR9) -> 0.42519788 | FR9: 0.031 | FS9: =FR9/FQ9 -> 0.072907231 | FV9: =SQRT(AVERAGE(ES9:EY9))/AVERAGE(AB9:AH9) -> 0.01641507 | FW9: =FR9/FV9 -> 1.8885086 | FY9: =FY8+1 -> 14 | FZ9: =COUNTIF($AY$7:$AY$106,FY9) -> 32 | GA9: =COUNTIFS($I$7:$I$106,"Fixed",$AY$7:$AY$106,$FY9) -> 25 | GB9: =COUNTIFS($I$7:$I$106,"Tracker",$AY$7:$AY$106,$FY9) -> 7
A10: =A9+1 -> 4 | B10: 56900 | C10: Atlantic Cty ConvCtr | D10: 2009 | E10: 2008 | F10: Commercial Non-CHP | G10: c-Si | H10: Unknown | I10: Fixed | J10: 10 | K10: NJ | L10: 39.36 | M10: -74.44 | N10: 2.4 | O10: 2 | P10: =365.25*4.3 -> 1570.575 | Q10: Atlantic City | R10: 11.7 | S10: =R10+11.448+2.715*IF($I10="Tracker",P10*0.95,P10)/365.25 -> 34.8225 | T10: =IF(S10>=50,"H",IF(S10>=40,"M","C")) -> C | U10: 1486 | V10: 672 | W10: 0.509 | X10: =V10/U10 -> 0.45222073 | Y10: =MAX(0,IF($I10="Tracker",P10*0.95,P10)*(N10/O10)*0.0000994+0.3284*X10-0.358) -> 0 | Z10: =EXP(-12.9*Y10) -> 1 | AA10: =N10*P10*INDEX($C$3:$D$4,MATCH(I10,$C$3:$C$4,0),2)*CH10 -> 3095.4399 | AB10: 2767 | AC10: 3028 | AD10: 3069 | AE10: 3066 | AF10: 2850 | AG10: 2979 | AH10: 2982 | AI10: 3062 | AJ10: 2990 | AK10: 2899 | AL10: 3117 | AM10: 3054 | AN10: 2986 | AO10: 3094 | AP10: 2817 | AQ10: 2075 | AY10: 16 | AZ10: =SUM(AB10:AX10)/AY10/N10/P10 -> 0.77657002 | BA10: =A10 -> 4 | BB10: =IF(ISNUMBER(AB10),MIN(1.15,AB10/($AA10*(1-$K$3)^(BB$6-1))),"") -> 0.89389556 | BC10: =IF(ISNUMBER(AC10),MIN(1.15,AC10/($AA10*(1-$K$3)^(BC$6-1))),"") -> 0.98312878 | BD10: =IF(ISNUMBER(AD10),MIN(1.15,AD10/($AA10*(1-$K$3)^(BD$6-1))),"") -> 1.0014479 | BE10: =IF(ISNUMBER(AE10),MIN(1.15,AE10/($AA10*(1-$K$3)^(BE$6-1))),"") -> 1.0054964 | BF10: =IF(ISNUMBER(AF10),MIN(1.15,AF10/($AA10*(1-$K$3)^(BF$6-1))),"") -> 0.93935588 | BG10: =IF(ISNUMBER(AG10),MIN(1.15,AG10/($AA10*(1-$K$3)^(BG$6-1))),"") -> 0.98680813 | BH10: =IF(ISNUMBER(AH10),MIN(1.15,AH10/($AA10*(1-$K$3)^(BH$6-1))),"") -> 0.99276573 | BI10: =IF(ISNUMBER(AI10),MIN(1.15,AI10/($AA10*(1-$K$3)^(BI$6-1))),"") -> 1.0245219 | ... BQ10: =IF(ISNUMBER(AQ10),MIN(1.15,AQ10/($AA10*(1-$K$3)^(BQ$6-1))),"") -> 0.72268578 | BY10: =A10 -> 4 | BZ10: =$AA10*IF($K$3=0,$AY10,((1-$K$3)^$AY10-1)/-$K$3) -> 47712.415 | CA10: =SUM(AB10:AX10) -> 46835 | CB10: =CA10/BZ10 -> 0.98161034 | CC10: =ROUND(RANK(CB10,$CB$7:$CB$106,0),0) -> 14 | CD10: =I10 -> Fixed | CE10: =CF10/(CG10+CF10*AY10/2) -> -0.0058961927 | CF10: {=LINEST(AB10:AQ10,AB$6:AQ$6,TRUE,FALSE)} -> -17.310294 | CG10: 3074.325 | CH10: =1+IF(G10="CdSCdTe",-0.0025,-0.004)*(S10-$S$4) -> 1.0265083 | CI10: NC | CJ10: =COUNTIF($K$7:$K$106,$CI10) -> 7 | CK10: =AVERAGEIF($K$7:$K$106,$CI10,$CB$7:$CB$106) -> 0.79313051 | CL10: =AVERAGEIF($K$7:$K$106,$CI10,$CE$7:$CE$106) -> -0.040097536 | CO10: All | CP10: =SUM(CP7:CP9) -> 100 | CQ10: =AVERAGE($CB$7:$CB$106) -> 0.83956393 | CR10: =AVERAGE($CE$7:$CE$106) -> -0.031107464 | CY10: Electric Utility | CZ10: =AVERAGEIF($F$7:$F$106,$CY10,$CB$7:$CB$106) -> 0.84702396 | DA10: =AVERAGEIF($F$7:$F$106,$CY10,$CE$7:$CE$106) -> -0.031730114 | DB10: =COUNTIF($F$7:$F$106,$CY10) -> 24 | DC10: =N10/O10 -> 1.2 | DD10: =D10-E10 -> 1 | DE10: =AY10+DD10 -> 17 | DJ10: First Solar | DK10: =COUNTIF($H$7:$H$106,$DJ10) -> 10 | DL10: =SUMIF($H$7:$H$106,$DJ10,$N$7:$N$106) -> 167.03638 | DM10: =AVERAGEIF($H$7:$H$106,$DJ10,$CB$7:$CB$106) -> 0.9172278 | DN10: =AVERAGEIF($H$7:$H$106,$DJ10,$CE$7:$CE$106) -> -0.0131601 | DP10: Si_IBC | DQ10: =COUNTIF($G$7:$G$106,$DP10) -> 5 | DT10: =SUM(AB10:AH10) -> 20741 | DU10: =IF(BB10>0,AB10/BB10,$AA10) -> 3095.4399 | DV10: =IF(BC10>0,AC10/BC10,$AA10) -> 3079.9627 | DW10: =IF(BD10>0,AD10/BD10,$AA10) -> 3064.5629 | DX10: =IF(BE10>0,AE10/BE10,$AA10) -> 3049.2401 | DY10: =IF(BF10>0,AF10/BF10,$AA10) -> 3033.9939 | DZ10: =IF(BG10>0,AG10/BG10,$AA10) -> 3018.8239 | EA10: =IF(BH10>0,AH10/BH10,$AA10) -> 3003.7298 | EB10: =DT10/SUM(DU10:EA10) -> 0.97166868 | ED10: =IF($T10="H",CB10," ") | EE10: =IF($T10="H",$CE10," ") | EF10: =IF($T10="C",CB10," ") -> 0.98161034 | EG10: =IF($T10="C",CE10," ") -> -0.0058961927 | EI10: =IF($T10="H",$EB10," ") | EJ10: =IF($T10="C",$EB10," ") -> 0.97166868 | EL10: {=LINEST($AB10:$AH10,$AB$6:$AH$6,TRUE,FALSE)} -> 11.714286 | EM10: 2916.1429 | EN10: =EL10/(EL10*($AB$6+$AH$6)*0.5+EM10) -> 0.003953522 | EO10: {=LINEST($AH10:$AQ10,$AH$6:$AQ$6,TRUE,FALSE)} -> -55.515152 | EP10: 3546.0242 | EQ10: =EO10/(EO10*(AY10/2+7/2)+EP10) -> -0.019093119 | ES10: =($EM10+$EL10*ES$6-AB10)^2 -> 25875.02 | ET10: =($EM10+$EL10*ET$6-AC10)^2 -> 7819.6122 | EU10: =($EM10+$EL10*EU$6-AD10)^2 -> 13856.653 | EV10: =($EM10+$EL10*EV$6-AE10)^2 -> 10609 | EW10: =($EM10+$EL10*EW$6-AF10)^2 -> 15553.653 | EX10: =($EM10+$EL10*EX$6-AG10)^2 -> 55.183673 | EY10: =($EM10+$EL10*EY$6-AH10)^2 -> 260.59184 | EZ10: =($EP10+$EO10*EZ$6-AI10)^2 -> 1592.2518 | FA10: =($EP10+$EO10*FA$6-AJ10)^2 -> 3179.5929 | FB10: =($EP10+$EO10*FB$6-AK10)^2 -> 8440.598 | FC10: =($EP10+$EO10*FC$6-AL10)^2 -> 32993.97 | FD10: =($EP10+$EO10*FD$6-AM10)^2 -> 30330.861 | FE10: =($EP10+$EO10*FE$6-AN10)^2 -> 26138.071 | FF10: =($EP10+$EO10*FF$6-AO10)^2 -> 105747.16 | FG10: =($EP10+$EO10*FG$6-AP10)^2 -> 10754.318 | FH10: =($EP10+$EO10*FH$6-AQ10)^2 -> 339634.65 | FQ10: =SQRT(AVERAGE(ES10:FH10))/AVERAGE(AB10:AQ10) -> 0.067941766 | FR10: 0.0275 | FS10: =FR10/FQ10 -> 0.40475839 | FV10: =SQRT(AVERAGE(ES10:EY10))/AVERAGE(AB10:AH10) -> 0.034707423 | FW10: =FR10/FV10 -> 0.79233772 | FY10: =FY9+1 -> 15 | FZ10: =COUNTIF($AY$7:$AY$106,FY10) -> 17 | GA10: =COUNTIFS($I$7:$I$106,"Fixed",$AY$7:$AY$106,$FY10) -> 13 | GB10: =COUNTIFS($I$7:$I$106,"Tracker",$AY$7:$AY$106,$FY10) -> 4
A11: =A10+1 -> 5 | B11: 56862 | C11: MMA Bolthouse | D11: 2009 | E11: 2008 | F11: IPP Non-CHP | G11: c-Si | H11: MMA | I11: Tracker | J11: 15 | K11: CA | L11: 34.56 | M11: -117.69 | N11: =10300*185/1000000 -> 1.9055 | O11: 1.5 | P11: =365.25*(8.4*0.75+9*0.25) -> 3122.8875 | Q11: Daggett | R11: 19.8 | S11: =R11+11.448+2.715*IF($I11="Tracker",P11*0.95,P11)/365.25 -> 53.300588 | T11: =IF(S11>=50,"H",IF(S11>=40,"M","C")) -> H | U11: 2138 | V11: 489 | W11: 0.696 | X11: =V11/U11 -> 0.22871843 | Y11: =MAX(0,IF($I11="Tracker",P11*0.95,P11)*(N11/O11)*0.0000994+0.3284*X11-0.358) -> 0.091725149 | Z11: =EXP(-12.9*Y11) -> 0.30628035 | AA11: =N11*P11*INDEX($C$3:$D$4,MATCH(I11,$C$3:$C$4,0),2)*CH11 -> 4308.1183 | AB11: 2526 | AC11: 2586.87 | AD11: 4298.58 | AE11: 4231 | AF11: 4053 | AG11: 4089 | AH11: 2259 | AI11: 3778 | AJ11: 3270 | AK11: 1886 | AL11: 3325 | AM11: 2779 | AN11: 1548 | AO11: 857 | AP11: 93 | AQ11: 67 | AY11: 16 | AZ11: =SUM(AB11:AX11)/AY11/N11/P11 -> 0.43741403 | BA11: =A11 -> 5 | BB11: =IF(ISNUMBER(AB11),MIN(1.15,AB11/($AA11*(1-$K$3)^(BB$6-1))),"") -> 0.58633487 | BC11: =IF(ISNUMBER(AC11),MIN(1.15,AC11/($AA11*(1-$K$3)^(BC$6-1))),"") -> 0.60348142 | BD11: =IF(ISNUMBER(AD11),MIN(1.15,AD11/($AA11*(1-$K$3)^(BD$6-1))),"") -> 1.0078392 | BE11: =IF(ISNUMBER(AE11),MIN(1.15,AE11/($AA11*(1-$K$3)^(BE$6-1))),"") -> 0.99697935 | BF11: =IF(ISNUMBER(AF11),MIN(1.15,AF11/($AA11*(1-$K$3)^(BF$6-1))),"") -> 0.95983517 | BG11: =IF(ISNUMBER(AG11),MIN(1.15,AG11/($AA11*(1-$K$3)^(BG$6-1))),"") -> 0.97322686 | BH11: =IF(ISNUMBER(AH11),MIN(1.15,AH11/($AA11*(1-$K$3)^(BH$6-1))),"") -> 0.54036863 | BI11: =IF(ISNUMBER(AI11),MIN(1.15,AI11/($AA11*(1-$K$3)^(BI$6-1))),"") -> 0.90826539 | ... BQ11: =IF(ISNUMBER(AQ11),MIN(1.15,AQ11/($AA11*(1-$K$3)^(BQ$6-1))),"") -> 0.016766444 | BY11: =A11 -> 5 | BZ11: =$AA11*IF($K$3=0,$AY11,((1-$K$3)^$AY11-1)/-$K$3) -> 66404.367 | CA11: =SUM(AB11:AX11) -> 41646.45 | CB11: =CA11/BZ11 -> 0.62716432 | CC11: =ROUND(RANK(CB11,$CB$7:$CB$106,0),0) -> 93 | CD11: =I11 -> Tracker | CE11: =CF11/(CG11+CF11*AY11/2) -> -0.079050241 | CF11: {=LINEST(AB11:AQ11,AB$6:AQ$6,TRUE,FALSE)} -> -214.22749 | CG11: 4423.8367 | CH11: =1+IF(G11="CdSCdTe",-0.0025,-0.004)*(S11-$S$4) -> 0.95259596 | CI11: PA | CJ11: =COUNTIF($K$7:$K$106,$CI11) -> 6 | CK11: =AVERAGEIF($K$7:$K$106,$CI11,$CB$7:$CB$106) -> 0.83363143 | CL11: =AVERAGEIF($K$7:$K$106,$CI11,$CE$7:$CE$106) -> -0.022020272 | CY11: Industrial Non-CHP | CZ11: =AVERAGEIF($F$7:$F$106,$CY11,$CB$7:$CB$106) -> 0.90204819 | DA11: =AVERAGEIF($F$7:$F$106,$CY11,$CE$7:$CE$106) -> -0.014343824 | DB11: =COUNTIF($F$7:$F$106,$CY11) -> 2 | DC11: =N11/O11 -> 1.2703333 | DD11: =D11-E11 -> 1 | DE11: =AY11+DD11 -> 17 | DJ11: MMA | DK11: =COUNTIF($H$7:$H$106,$DJ11) -> 6 | DL11: =SUMIF($H$7:$H$106,$DJ11,$N$7:$N$106) -> 12.8785 | DM11: =AVERAGEIF($H$7:$H$106,$DJ11,$CB$7:$CB$106) -> 0.77372153 | DN11: =AVERAGEIF($H$7:$H$106,$DJ11,$CE$7:$CE$106) -> -0.041147449 | DP11: Unknown | DQ11: =COUNTIF($G$7:$G$106,$DP11) -> 0 | DT11: =SUM(AB11:AH11) -> 24043.45 | DU11: =IF(BB11>0,AB11/BB11,$AA11) -> 4308.1183 | DV11: =IF(BC11>0,AC11/BC11,$AA11) -> 4286.5777 | DW11: =IF(BD11>0,AD11/BD11,$AA11) -> 4265.1448 | DX11: =IF(BE11>0,AE11/BE11,$AA11) -> 4243.8191 | DY11: =IF(BF11>0,AF11/BF11,$AA11) -> 4222.6 | DZ11: =IF(BG11>0,AG11/BG11,$AA11) -> 4201.487 | EA11: =IF(BH11>0,AH11/BH11,$AA11) -> 4180.4796 | EB11: =DT11/SUM(DU11:EA11) -> 0.8093196 | ED11: =IF($T11="H",CB11," ") -> 0.62716432 | EE11: =IF($T11="H",$CE11," ") -> -0.079050241 | EF11: =IF($T11="C",CB11," ") | EG11: =IF($T11="C",CE11," ") | EI11: =IF($T11="H",$EB11," ") -> 0.8093196 | EJ11: =IF($T11="C",$EB11," ") | EL11: {=LINEST($AB11:$AH11,$AB$6:$AH$6,TRUE,FALSE)} -> 69.917143 | EM11: 3155.11 | EN11: =EL11/(EL11*($AB$6+$AH$6)*0.5+EM11) -> 0.020355648 | EO11: {=LINEST($AH11:$AQ11,$AH$6:$AQ$6,TRUE,FALSE)} -> -358.47273 | EP11: 6108.6364 | EQ11: =EO11/(EO11*(AY11/2+7/2)+EP11) -> -0.18048169 | ES11: =($EM11+$EL11*ES$6-AB11)^2 -> 488638.95 | ET11: =($EM11+$EL11*ET$6-AC11)^2 -> 501369.19 | EU11: =($EM11+$EL11*EU$6-AD11)^2 -> 871830.37 | EV11: =($EM11+$EL11*EV$6-AE11)^2 -> 633968.56 | EW11: =($EM11+$EL11*EW$6-AF11)^2 -> 300637.59 | EX11: =($EM11+$EL11*EX$6-AG11)^2 -> 264594.13 | EY11: =($EM11+$EL11*EY$6-AH11)^2 -> 1919693.4 | EZ11: =($EP11+$EO11*EZ$6-AI11)^2 -> 288525.24 | FA11: =($EP11+$EO11*FA$6-AJ11)^2 -> 150247.85 | FB11: =($EP11+$EO11*FB$6-AK11)^2 -> 406928.01 | FC11: =($EP11+$EO11*FC$6-AL11)^2 -> 1344587.8 | FD11: =($EP11+$EO11*FD$6-AM11)^2 -> 944854.69 | FE11: =($EP11+$EO11*FE$6-AN11)^2 -> 9902.0592 | FF11: =($EP11+$EO11*FF$6-AO11)^2 -> 54297.473 | FG11: =($EP11+$EO11*FG$6-AP11)^2 -> 407740.3 | FH11: =($EP11+$EO11*FH$6-AQ11)^2 -> 93680.514 | FQ11: =SQRT(AVERAGE(ES11:FH11))/AVERAGE(AB11:AQ11) -> 0.28299535 | FR11: 0.028 | FS11: =FR11/FQ11 -> 0.098941557 | FV11: =SQRT(AVERAGE(ES11:EY11))/AVERAGE(AB11:AH11) -> 0.2455833 | FW11: =FR11/FV11 -> 0.11401427 | FY11: =FY10+1 -> 16 | FZ11: =COUNTIF($AY$7:$AY$106,FY11) -> 20 | GA11: =COUNTIFS($I$7:$I$106,"Fixed",$AY$7:$AY$106,$FY11) -> 10 | GB11: =COUNTIFS($I$7:$I$106,"Tracker",$AY$7:$AY$106,$FY11) -> 10
A12: =A11+1 -> 6 | B12: 56944 | C12: Copper Mtn10 (FS) | D12: 2009 | E12: 2008 | F12: IPP Non-CHP | G12: CdSCdTe | H12: First Solar | I12: Fixed | J12: 25 | K12: NV | L12: 35.79 | M12: -114.99 | N12: 12.4 | O12: 10 | P12: =365.25*6.4 -> 2337.6 | Q12: Las Vegas | R12: 19.5 | S12: =R12+11.448+2.715*IF($I12="Tracker",P12*0.95,P12)/365.25 -> 48.324 | T12: =IF(S12>=50,"H",IF(S12>=40,"M","C")) -> M | U12: 2078 | V12: 550 | W12: 0.684 | X12: =V12/U12 -> 0.26467757 | Y12: =MAX(0,IF($I12="Tracker",P12*0.95,P12)*(N12/O12)*0.0000994+0.3284*X12-0.358) -> 0.017043341 | Z12: =EXP(-12.9*Y12) -> 0.80263188 | AA12: =N12*P12*INDEX($C$3:$D$4,MATCH(I12,$C$3:$C$4,0),2)*CH12 -> 22790.465 | AB12: 21661 | AC12: 21146 | AD12: 21546 | AE12: 21245 | AF12: 20375 | AG12: 19869 | AH12: 19885 | AI12: 19061 | AJ12: 19321 | AK12: 19595 | AL12: 22562 | AM12: 21953 | AN12: 18686 | AO12: 18948 | AP12: 19201 | AQ12: 17988 | AY12: 16 | AZ12: =SUM(AB12:AX12)/AY12/N12/P12 -> 0.6965417 | BA12: =A12 -> 6 | BB12: =IF(ISNUMBER(AB12),MIN(1.15,AB12/($AA12*(1-$K$3)^(BB$6-1))),"") -> 0.95044135 | BC12: =IF(ISNUMBER(AC12),MIN(1.15,AC12/($AA12*(1-$K$3)^(BC$6-1))),"") -> 0.93250671 | BD12: =IF(ISNUMBER(AD12),MIN(1.15,AD12/($AA12*(1-$K$3)^(BD$6-1))),"") -> 0.95492071 | BE12: =IF(ISNUMBER(AE12),MIN(1.15,AE12/($AA12*(1-$K$3)^(BE$6-1))),"") -> 0.94631192 | BF12: =IF(ISNUMBER(AF12),MIN(1.15,AF12/($AA12*(1-$K$3)^(BF$6-1))),"") -> 0.91212028 | BG12: =IF(ISNUMBER(AG12),MIN(1.15,AG12/($AA12*(1-$K$3)^(BG$6-1))),"") -> 0.89393805 | BH12: =IF(ISNUMBER(AH12),MIN(1.15,AH12/($AA12*(1-$K$3)^(BH$6-1))),"") -> 0.89915369 | BI12: =IF(ISNUMBER(AI12),MIN(1.15,AI12/($AA12*(1-$K$3)^(BI$6-1))),"") -> 0.86622544 | ... BQ12: =IF(ISNUMBER(AQ12),MIN(1.15,AQ12/($AA12*(1-$K$3)^(BQ$6-1))),"") -> 0.85090972 | BY12: =A12 -> 6 | BZ12: =$AA12*IF($K$3=0,$AY12,((1-$K$3)^$AY12-1)/-$K$3) -> 351287.1 | CA12: =SUM(AB12:AX12) -> 323042 | CB12: =CA12/BZ12 -> 0.9195954 | CC12: =ROUND(RANK(CB12,$CB$7:$CB$106,0),0) -> 32 | CD12: =I12 -> Fixed | CE12: =CF12/(CG12+CF12*AY12/2) -> -0.0078419372 | CF12: {=LINEST(AB12:AQ12,AB$6:AQ$6,TRUE,FALSE)} -> -158.95294 | CG12: 21541.225 | CH12: =1+IF(G12="CdSCdTe",-0.0025,-0.004)*(S12-$S$4) -> 0.98281395 | CI12: AZ | CJ12: =COUNTIF($K$7:$K$106,$CI12) -> 6 | CK12: =AVERAGEIF($K$7:$K$106,$CI12,$CB$7:$CB$106) -> 0.73107182 | CL12: =AVERAGEIF($K$7:$K$106,$CI12,$CE$7:$CE$106) -> -0.050734559 | CN12: =CN9 -> 0.47 | CO12: Cold | CP12: =CP9 -> 47 | CY12: IPP Non-CHP | CZ12: =AVERAGEIF($F$7:$F$106,$CY12,$CB$7:$CB$106) -> 0.84860718 | DA12: =AVERAGEIF($F$7:$F$106,$CY12,$CE$7:$CE$106) -> -0.027449549 | DB12: =COUNTIF($F$7:$F$106,$CY12) -> 63 | DC12: =N12/O12 -> 1.24 | DD12: =D12-E12 -> 1 | DE12: =AY12+DD12 -> 17 | DJ12: NextEra | DK12: =COUNTIF($H$7:$H$106,$DJ12) -> 0 | DL12: =SUMIF($H$7:$H$106,$DJ12,$N$7:$N$106) -> 0 | DQ12: =SUM(DQ7:DQ11) -> 100 | DT12: =SUM(AB12:AH12) -> 145727 | DU12: =IF(BB12>0,AB12/BB12,$AA12) -> 22790.465 | DV12: =IF(BC12>0,AC12/BC12,$AA12) -> 22676.512 | DW12: =IF(BD12>0,AD12/BD12,$AA12) -> 22563.13 | DX12: =IF(BE12>0,AE12/BE12,$AA12) -> 22450.314 | DY12: =IF(BF12>0,AF12/BF12,$AA12) -> 22338.063 | DZ12: =IF(BG12>0,AG12/BG12,$AA12) -> 22226.372 | EA12: =IF(BH12>0,AH12/BH12,$AA12) -> 22115.24 | EB12: =DT12/SUM(DU12:EA12) -> 0.92725191 | ED12: =IF($T12="H",CB12," ") | EE12: =IF($T12="H",$CE12," ") | EF12: =IF($T12="C",CB12," ") | EG12: =IF($T12="C",CE12," ") | EI12: =IF($T12="H",$EB12," ") | EJ12: =IF($T12="C",$EB12," ") | EL12: {=LINEST($AB12:$AH12,$AB$6:$AH$6,TRUE,FALSE)} -> -323.32143 | EM12: 22111.429 | EN12: =EL12/(EL12*($AB$6+$AH$6)*0.5+EM12) -> -0.015530753 | EO12: {=LINEST($AH12:$AQ12,$AH$6:$AQ$6,TRUE,FALSE)} -> -129.05455 | EP12: 21204.127 | EQ12: =EO12/(EO12*(AY12/2+7/2)+EP12) -> -0.0065443481 | ES12: =($EM12+$EL12*ES$6-AB12)^2 -> 16156.226 | ET12: =($EM12+$EL12*ET$6-AC12)^2 -> 101624.33 | EU12: =($EM12+$EL12*EU$6-AD12)^2 -> 163649.14 | EV12: =($EM12+$EL12*EV$6-AE12)^2 -> 182207.02 | EW12: =($EM12+$EL12*EW$6-AF12)^2 -> 14357.175 | EX12: =($EM12+$EL12*EX$6-AG12)^2 -> 91506.25 | EY12: =($EM12+$EL12*EY$6-AH12)^2 -> 1355.8176 | EZ12: =($EP12+$EO12*EZ$6-AI12)^2 -> 1233634.3 | FA12: =($EP12+$EO12*FA$6-AJ12)^2 -> 520759.04 | FB12: =($EP12+$EO12*FB$6-AK12)^2 -> 101494.37 | FC12: =($EP12+$EO12*FC$6-AL12)^2 -> 7714354.8 | FD12: =($EP12+$EO12*FD$6-AM12)^2 -> 5278631.6 | FE12: =($EP12+$EO12*FE$6-AN12)^2 -> 706302.72 | FF12: =($EP12+$EO12*FF$6-AO12)^2 -> 201927.68 | FG12: =($EP12+$EO12*FG$6-AP12)^2 -> 4530.5137 | FH12: =($EP12+$EO12*FH$6-AQ12)^2 -> 1325387 | FQ12: =SQRT(AVERAGE(ES12:FH12))/AVERAGE(AB12:AQ12) -> 0.052031968 | FR12: 0.03 | FS12: =FR12/FQ12 -> 0.57656862 | FV12: =SQRT(AVERAGE(ES12:EY12))/AVERAGE(AB12:AH12) -> 0.013717415 | FW12: =FR12/FV12 -> 2.187001 | FY12: =FY11+1 -> 17 | FZ12: =COUNTIF($AY$7:$AY$106,FY12) -> 3 | GA12: =COUNTIFS($I$7:$I$106,"Fixed",$AY$7:$AY$106,$FY12) -> 1 | GB12: =COUNTIFS($I$7:$I$106,"Tracker",$AY$7:$AY$106,$FY12) -> 2
A13: =A12+1 -> 7 | B13: 56813 | C13: CSU Fresno MMA | D13: 2008 | E13: 2007 | F13: IPP Non-CHP | G13: c-Si | H13: MMA | I13: Fixed | J13: 2 | K13: CA | L13: 36.80984 | M13: -119.74167 | N13: 1.173 | O13: 1 | P13: =365.25*5.2*1.02 -> 1937.286 | Q13: Fresno | R13: 17.4 | S13: =R13+11.448+2.715*IF($I13="Tracker",P13*0.95,P13)/365.25 -> 43.24836 | T13: =IF(S13>=50,"H",IF(S13>=40,"M","C")) -> M | U13: 1910 | V13: 578 | W13: 0.634 | X13: =V13/U13 -> 0.3026178 | Y13: =MAX(0,IF($I13="Tracker",P13*0.95,P13)*(N13/O13)*0.0000994+0.3284*X13-0.358) -> 0 | Z13: =EXP(-12.9*Y13) -> 1 | AA13: 1547 | AB13: 1442 | AC13: 1655 | AD13: 1123 | AE13: 981 | AF13: 1556 | AG13: 1564 | AH13: 1453 | AI13: 1466 | AJ13: 1445 | AK13: 1452 | AL13: 1294 | AM13: 1485 | AN13: 1149 | AO13: 1059 | AP13: 592 | AQ13: 1094 | AR13: 1438 | AY13: 17 | AZ13: =SUM(AB13:AX13)/AY13/N13/P13 -> 0.57590428 | BA13: =A13 -> 7 | BB13: =IF(ISNUMBER(AB13),MIN(1.15,AB13/($AA13*(1-$K$3)^(BB$6-1))),"") -> 0.9321267 | BC13: =IF(ISNUMBER(AC13),MIN(1.15,AC13/($AA13*(1-$K$3)^(BC$6-1))),"") -> 1.0751885 | BD13: =IF(ISNUMBER(AD13),MIN(1.15,AD13/($AA13*(1-$K$3)^(BD$6-1))),"") -> 0.73323516 | BE13: =IF(ISNUMBER(AE13),MIN(1.15,AE13/($AA13*(1-$K$3)^(BE$6-1))),"") -> 0.64373845 | BF13: =IF(ISNUMBER(AF13),MIN(1.15,AF13/($AA13*(1-$K$3)^(BF$6-1))),"") -> 1.0261881 | BG13: =IF(ISNUMBER(AG13),MIN(1.15,AG13/($AA13*(1-$K$3)^(BG$6-1))),"") -> 1.0366473 | BH13: =IF(ISNUMBER(AH13),MIN(1.15,AH13/($AA13*(1-$K$3)^(BH$6-1))),"") -> 0.9679141 | BI13: =IF(ISNUMBER(AI13),MIN(1.15,AI13/($AA13*(1-$K$3)^(BI$6-1))),"") -> 0.98148144 | ... BR13: =IF(ISNUMBER(AR13),MIN(1.15,AR13/($AA13*(1-$K$3)^(BR$6-1))),"") -> 1.0071619 | BY13: =A13 -> 7 | BZ13: =$AA13*IF($K$3=0,$AY13,((1-$K$3)^$AY13-1)/-$K$3) -> 25272.885 | CA13: =SUM(AB13:AX13) -> 22248 | CB13: =CA13/BZ13 -> 0.88031106 | CC13: =ROUND(RANK(CB13,$CB$7:$CB$106,0),0) -> 47 | CD13: =I13 -> Fixed | CE13: =CF13/(CG13+CF13*AY13/2) -> -0.016626178 | CF13: {=LINEST(AB13:AR13,AB$6:AR$6,TRUE,FALSE)} -> -21.941176 | CG13: 1506.1765 | CH13: =1+IF(G13="CdSCdTe",-0.0025,-0.004)*(S13-$S$4) -> 0.99280487 | CI13: FL | CJ13: =COUNTIF($K$7:$K$106,$CI13) -> 4 | CK13: =AVERAGEIF($K$7:$K$106,$CI13,$CB$7:$CB$106) -> 0.92455235 | CL13: =AVERAGEIF($K$7:$K$106,$CI13,$CE$7:$CE$106) -> -0.038031077 | CN13: =CN8 -> 0.41 | CO13: Medium | CP13: =CP8 -> 41 | CY13: All | CZ13: =AVERAGE($CB$7:$CB$106) -> 0.83956393 | DA13: =AVERAGE($CE$7:$CE$106) -> -0.031107464 | DB13: =SUM(DB9:DB12) -> 100 | DC13: =N13/O13 -> 1.173 | DD13: =D13-E13 -> 1 | DE13: =AY13+DD13 -> 18 | DJ13: NRG | DK13: =COUNTIF($H$7:$H$106,$DJ13) -> 1 | DL13: =SUMIF($H$7:$H$106,$DJ13,$N$7:$N$106) -> 26.4 | DM13: =AVERAGEIF($H$7:$H$106,$DJ13,$CB$7:$CB$106) -> 0.94175919 | DN13: =AVERAGEIF($H$7:$H$106,$DJ13,$CE$7:$CE$106) -> -0.015750661 | DT13: =SUM(AB13:AH13) -> 9774 | DU13: =IF(BB13>0,AB13/BB13,$AA13) -> 1547 | DV13: =IF(BC13>0,AC13/BC13,$AA13) -> 1539.265 | DW13: =IF(BD13>0,AD13/BD13,$AA13) -> 1531.5687 | DX13: =IF(BE13>0,AE13/BE13,$AA13) -> 1523.9108 | DY13: =IF(BF13>0,AF13/BF13,$AA13) -> 1516.2913 | DZ13: =IF(BG13>0,AG13/BG13,$AA13) -> 1508.7098 | EA13: =IF(BH13>0,AH13/BH13,$AA13) -> 1501.1663 | EB13: =DT13/SUM(DU13:EA13) -> 0.91620554 | ED13: =IF($T13="H",CB13," ") | EE13: =IF($T13="H",$CE13," ") | EF13: =IF($T13="C",CB13," ") | EG13: =IF($T13="C",CE13," ") | EI13: =IF($T13="H",$EB13," ") | EJ13: =IF($T13="C",$EB13," ") | EL13: {=LINEST($AB13:$AH13,$AB$6:$AH$6,TRUE,FALSE)} -> 10.142857 | EM13: 1355.7143 | EN13: =EL13/(EL13*($AB$6+$AH$6)*0.5+EM13) -> 0.0072641702 | EO13: {=LINEST($AH13:$AR13,$AH$6:$AR$6,TRUE,FALSE)} -> -45.936364 | EP13: 1817.3273 | EQ13: =EO13/(EO13*(AY13/2+7/2)+EP13) -> -0.036282042 | ES13: =($EM13+$EL13*ES$6-AB13)^2 -> 5797.7347 | ET13: =($EM13+$EL13*ET$6-AC13)^2 -> 77841 | EU13: =($EM13+$EL13*EU$6-AD13)^2 -> 69244.163 | EV13: =($EM13+$EL13*EV$6-AE13)^2 -> 172462.22 | EW13: =($EM13+$EL13*EW$6-AF13)^2 -> 22371.612 | EX13: =($EM13+$EL13*EX$6-AG13)^2 -> 21735.184 | EY13: =($EM13+$EL13*EY$6-AH13)^2 -> 690.93878 | EZ13: =($EP13+$EO13*EZ$6-AI13)^2 -> 261.26314 | FA13: =($EP13+$EO13*FA$6-AJ13)^2 -> 1689.21 | FB13: =($EP13+$EO13*FB$6-AK13)^2 -> 8842.8377 | FC13: =($EP13+$EO13*FC$6-AL13)^2 -> 324.98256 | FD13: =($EP13+$EO13*FD$6-AM13)^2 -> 47921.19 | FE13: =($EP13+$EO13*FE$6-AN13)^2 -> 5062.9693 | FF13: =($EP13+$EO13*FF$6-AO13)^2 -> 13275.229 | FG13: =($EP13+$EO13*FG$6-AP13)^2 -> 287598.19 | ... FI13: =($EP13+$EO13*FI$6-AR13)^2 -> 161275.26 | FQ13: =SQRT(AVERAGE(ES13:FI13))/AVERAGE(AB13:AR13) -> 0.17547524 | FR13: 0.03 | FS13: =FR13/FQ13 -> 0.17096429 | FV13: =SQRT(AVERAGE(ES13:EY13))/AVERAGE(AB13:AH13) -> 0.16468778 | FW13: =FR13/FV13 -> 0.18216288 | FY13: =FY12+1 -> 18 | FZ13: =COUNTIF($AY$7:$AY$106,FY13) -> 0 | GA13: =COUNTIFS($I$7:$I$106,"Fixed",$AY$7:$AY$106,$FY13) -> 0 | GB13: =COUNTIFS($I$7:$I$106,"Tracker",$AY$7:$AY$106,$FY13) -> 0
A14: =A13+1 -> 8 | B14: 10823 | C14: Deer Island | D14: 2011 | E14: 2008 | F14: Commercial CHP | G14: c-Si | H14: Unknown | I14: Fixed | J14: 15 | K14: MA | L14: 42.353 | M14: -70.963 | N14: 0.736 | O14: 0.666 | P14: =365.25*4.2 -> 1534.05 | Q14: Boston | R14: 10.7 | S14: =R14+11.448+2.715*IF($I14="Tracker",P14*0.95,P14)/365.25 -> 33.551 | T14: =IF(S14>=50,"H",IF(S14>=40,"M","C")) -> C | U14: 1432 | V14: 652 | W14: 0.509 | X14: =V14/U14 -> 0.45530726 | Y14: =MAX(0,IF($I14="Tracker",P14*0.95,P14)*(N14/O14)*0.0000994+0.3284*X14-0.358) -> 0 | Z14: =EXP(-12.9*Y14) -> 1 | AA14: =N14*P14*INDEX($C$3:$D$4,MATCH(I14,$C$3:$C$4,0),2)*CH14 -> 931.78616 | AB14: 646 | AC14: 879 | AD14: 881 | AE14: 0 | AF14: 835 | AG14: 872 | AH14: 826 | AI14: 799 | AJ14: 808 | AK14: 1123 | AL14: 760 | AM14: 794 | AN14: 628 | AO14: 625 | AP14: 621 | AY14: 15 | AZ14: =SUM(AB14:AX14)/AY14/N14/P14 -> 0.65523486 | BA14: =A14 -> 8 | BB14: =IF(ISNUMBER(AB14),MIN(1.15,AB14/($AA14*(1-$K$3)^(BB$6-1))),"") -> 0.69329212 | BC14: =IF(ISNUMBER(AC14),MIN(1.15,AC14/($AA14*(1-$K$3)^(BC$6-1))),"") -> 0.94808994 | BD14: =IF(ISNUMBER(AD14),MIN(1.15,AD14/($AA14*(1-$K$3)^(BD$6-1))),"") -> 0.95502225 | BE14: =IF(ISNUMBER(AE14),MIN(1.15,AE14/($AA14*(1-$K$3)^(BE$6-1))),"") -> 0 | BF14: =IF(ISNUMBER(AF14),MIN(1.15,AF14/($AA14*(1-$K$3)^(BF$6-1))),"") -> 0.91427722 | BG14: =IF(ISNUMBER(AG14),MIN(1.15,AG14/($AA14*(1-$K$3)^(BG$6-1))),"") -> 0.95958804 | BH14: =IF(ISNUMBER(AH14),MIN(1.15,AH14/($AA14*(1-$K$3)^(BH$6-1))),"") -> 0.91353525 | BI14: =IF(ISNUMBER(AI14),MIN(1.15,AI14/($AA14*(1-$K$3)^(BI$6-1))),"") -> 0.8881145 | ... BP14: =IF(ISNUMBER(AP14),MIN(1.15,AP14/($AA14*(1-$K$3)^(BP$6-1))),"") -> 0.71491139 | BY14: =A14 -> 8 | BZ14: =$AA14*IF($K$3=0,$AY14,((1-$K$3)^$AY14-1)/-$K$3) -> 13498.046 | CA14: =SUM(AB14:AX14) -> 11097 | CB14: =CA14/BZ14 -> 0.82211897 | CC14: =ROUND(RANK(CB14,$CB$7:$CB$106,0),0) -> 62 | CD14: =I14 -> Fixed | CE14: =CF14/(CG14+CF14*AY14/2) -> 0.0022763685 | CF14: {=LINEST(AB14:AP14,AB$6:AP$6,TRUE,FALSE)} -> 1.6821429 | CG14: 726.34286 | CH14: =1+IF(G14="CdSCdTe",-0.0025,-0.004)*(S14-$S$4) -> 1.0315943 | CI14: NM | CJ14: =COUNTIF($K$7:$K$106,$CI14) -> 4 | CK14: =AVERAGEIF($K$7:$K$106,$CI14,$CB$7:$CB$106) -> 0.95757876 | CL14: =AVERAGEIF($K$7:$K$106,$CI14,$CE$7:$CE$106) -> 0.0019565546 | CN14: =CN7 -> 0.12 | CO14: Hot | CP14: =CP7 -> 12 | DC14: =N14/O14 -> 1.1051051 | DD14: =D14-E14 -> 3 | DE14: =AY14+DD14 -> 18 | DJ14: Other utility | DK14: =COUNTIF($H$7:$H$106,$DJ14) -> 4 | DL14: =SUMIF($H$7:$H$106,$DJ14,$N$7:$N$106) -> 7.3576 | DM14: =AVERAGEIF($H$7:$H$106,$DJ14,$CB$7:$CB$106) -> 0.6694923 | DN14: =AVERAGEIF($H$7:$H$106,$DJ14,$CE$7:$CE$106) -> -0.049645173 | DT14: =SUM(AB14:AH14) -> 4939 | DU14: =IF(BB14>0,AB14/BB14,$AA14) -> 931.78616 | DV14: =IF(BC14>0,AC14/BC14,$AA14) -> 927.12723 | DW14: =IF(BD14>0,AD14/BD14,$AA14) -> 922.49159 | DX14: =IF(BE14>0,AE14/BE14,$AA14) -> 931.78616 | DY14: =IF(BF14>0,AF14/BF14,$AA14) -> 913.28974 | DZ14: =IF(BG14>0,AG14/BG14,$AA14) -> 908.72329 | EA14: =IF(BH14>0,AH14/BH14,$AA14) -> 904.17967 | EB14: =DT14/SUM(DU14:EA14) -> 0.76699885 | ED14: =IF($T14="H",CB14," ") | EE14: =IF($T14="H",$CE14," ") | EF14: =IF($T14="C",CB14," ") -> 0.82211897 | EG14: =IF($T14="C",CE14," ") -> 0.0022763685 | EI14: =IF($T14="H",$EB14," ") | EJ14: =IF($T14="C",$EB14," ") -> 0.76699885 | EL14: {=LINEST($AB14:$AH14,$AB$6:$AH$6,TRUE,FALSE)} -> 17.142857 | EM14: 637 | EN14: =EL14/(EL14*($AB$6+$AH$6)*0.5+EM14) -> 0.024296416 | EO14: {=LINEST($AH14:$AP14,$AH$6:$AP$6,TRUE,FALSE)} -> -33.85 | EP14: 1148.35 | EQ14: =EO14/(EO14*(AY14/2+7/2)+EP14) -> -0.043621134 | ES14: =($EM14+$EL14*ES$6-AB14)^2 -> 66.306122 | ET14: =($EM14+$EL14*ET$6-AC14)^2 -> 43145.224 | EU14: =($EM14+$EL14*EU$6-AD14)^2 -> 37083.755 | EV14: =($EM14+$EL14*EV$6-AE14)^2 -> 497831.04 | EW14: =($EM14+$EL14*EW$6-AF14)^2 -> 12608.082 | EX14: =($EM14+$EL14*EX$6-AG14)^2 -> 17461.735 | EY14: =($EM14+$EL14*EY$6-AH14)^2 -> 4761 | EZ14: =($EP14+$EO14*EZ$6-AI14)^2 -> 6170.1025 | FA14: =($EP14+$EO14*FA$6-AJ14)^2 -> 1274.49 | FB14: =($EP14+$EO14*FB$6-AK14)^2 -> 98062.923 | FC14: =($EP14+$EO14*FC$6-AL14)^2 -> 256 | FD14: =($EP14+$EO14*FD$6-AM14)^2 -> 2688.4225 | FE14: =($EP14+$EO14*FE$6-AN14)^2 -> 6448.09 | FF14: =($EP14+$EO14*FF$6-AO14)^2 -> 2445.3025 | FG14: =($EP14+$EO14*FG$6-AP14)^2 -> 384.16 | FQ14: =SQRT(AVERAGE(ES14:FG14))/AVERAGE(AB14:AP14) -> 0.29833597 | FR14: 0.029 | FS14: =FR14/FQ14 -> 0.097205843 | FV14: =SQRT(AVERAGE(ES14:EY14))/AVERAGE(AB14:AH14) -> 0.41939674 | FW14: =FR14/FV14 -> 0.069146937 | FY14: =FY13+1 -> 19 | FZ14: =COUNTIF($AY$7:$AY$106,FY14) -> 0 | GA14: =COUNTIFS($I$7:$I$106,"Fixed",$AY$7:$AY$106,$FY14) -> 0 | GB14: =COUNTIFS($I$7:$I$106,"Tracker",$AY$7:$AY$106,$FY14) -> 0
A15: =A14+1 -> 9 | B15: 56815 | C15: Denver airport MMA | D15: 2009 | E15: 2008 | F15: IPP Non-CHP | G15: c-Si | H15: MMA | I15: Tracker | J15: 0 | K15: CO | L15: 39.90298 | M15: -104.65925 | N15: 2 | O15: 1.9 | P15: =365.25*6.4 -> 2337.6 | Q15: Boulder | R15: 10.2 | S15: =R15+11.448+2.715*IF($I15="Tracker",P15*0.95,P15)/365.25 -> 38.1552 | T15: =IF(S15>=50,"H",IF(S15>=40,"M","C")) -> C | U15: 1689 | V15: 562 | W15: 0.583 | X15: =V15/U15 -> 0.33274127 | Y15: =MAX(0,IF($I15="Tracker",P15*0.95,P15)*(N15/O15)*0.0000994+0.3284*X15-0.358) -> 0 | Z15: =EXP(-12.9*Y15) -> 1 | AA15: =N15*P15*INDEX($C$3:$D$4,MATCH(I15,$C$3:$C$4,0),2)*CH15 -> 3599.9737 | AB15: 3255 | AC15: 3449 | AD15: 3287 | AE15: 3468 | AF15: 1469 | AG15: 2687 | AH15: 3027 | AI15: 3205 | AJ15: 2812 | AK15: 2539 | AL15: 2092 | AM15: 2284 | AN15: 1463 | AO15: 275 | AP15: 1595 | AQ15: 1541 | AY15: 16 | AZ15: =SUM(AB15:AX15)/AY15/N15/P15 -> 0.51398871 | BA15: =A15 -> 9 | BB15: =IF(ISNUMBER(AB15),MIN(1.15,AB15/($AA15*(1-$K$3)^(BB$6-1))),"") -> 0.90417327 | BC15: =IF(ISNUMBER(AC15),MIN(1.15,AC15/($AA15*(1-$K$3)^(BC$6-1))),"") -> 0.96287694 | BD15: =IF(ISNUMBER(AD15),MIN(1.15,AD15/($AA15*(1-$K$3)^(BD$6-1))),"") -> 0.92226179 | BE15: =IF(ISNUMBER(AE15),MIN(1.15,AE15/($AA15*(1-$K$3)^(BE$6-1))),"") -> 0.97793619 | BF15: =IF(ISNUMBER(AF15),MIN(1.15,AF15/($AA15*(1-$K$3)^(BF$6-1))),"") -> 0.41632275 | BG15: =IF(ISNUMBER(AG15),MIN(1.15,AG15/($AA15*(1-$K$3)^(BG$6-1))),"") -> 0.7653374 | BH15: =IF(ISNUMBER(AH15),MIN(1.15,AH15/($AA15*(1-$K$3)^(BH$6-1))),"") -> 0.86651205 | BI15: =IF(ISNUMBER(AI15),MIN(1.15,AI15/($AA15*(1-$K$3)^(BI$6-1))),"") -> 0.9220769 | ... BQ15: =IF(ISNUMBER(AQ15),MIN(1.15,AQ15/($AA15*(1-$K$3)^(BQ$6-1))),"") -> 0.46148448 | BY15: =A15 -> 9 | BZ15: =$AA15*IF($K$3=0,$AY15,((1-$K$3)^$AY15-1)/-$K$3) -> 55489.185 | CA15: =SUM(AB15:AX15) -> 38448 | CB15: =CA15/BZ15 -> 0.69289177 | CC15: =ROUND(RANK(CB15,$CB$7:$CB$106,0),0) -> 88 | CD15: =I15 -> Tracker | CE15: =CF15/(CG15+CF15*AY15/2) -> -0.059447847 | CF15: {=LINEST(AB15:AQ15,AB$6:AQ$6,TRUE,FALSE)} -> -147.22941 | CG15: 3654.45 | CH15: =1+IF(G15="CdSCdTe",-0.0025,-0.004)*(S15-$S$4) -> 1.0131775 | CI15: NV | CJ15: =COUNTIF($K$7:$K$106,$CI15) -> 4 | CK15: =AVERAGEIF($K$7:$K$106,$CI15,$CB$7:$CB$106) -> 0.88599696 | CL15: =AVERAGEIF($K$7:$K$106,$CI15,$CE$7:$CE$106) -> -0.017593185 | DC15: =N15/O15 -> 1.0526316 | DD15: =D15-E15 -> 1 | DE15: =AY15+DD15 -> 17 | DJ15: PG&E | DK15: =COUNTIF($H$7:$H$106,$DJ15) -> 4 | DL15: =SUMIF($H$7:$H$106,$DJ15,$N$7:$N$106) -> 63.3 | DM15: =AVERAGEIF($H$7:$H$106,$DJ15,$CB$7:$CB$106) -> 0.90141609 | DN15: =AVERAGEIF($H$7:$H$106,$DJ15,$CE$7:$CE$106) -> -0.042601682 | DT15: =SUM(AB15:AH15) -> 20642 | DU15: =IF(BB15>0,AB15/BB15,$AA15) -> 3599.9737 | DV15: =IF(BC15>0,AC15/BC15,$AA15) -> 3581.9738 | DW15: =IF(BD15>0,AD15/BD15,$AA15) -> 3564.064 | DX15: =IF(BE15>0,AE15/BE15,$AA15) -> 3546.2436 | DY15: =IF(BF15>0,AF15/BF15,$AA15) -> 3528.5124 | DZ15: =IF(BG15>0,AG15/BG15,$AA15) -> 3510.8699 | EA15: =IF(BH15>0,AH15/BH15,$AA15) -> 3493.3155 | EB15: =DT15/SUM(DU15:EA15) -> 0.83150208 | ED15: =IF($T15="H",CB15," ") | EE15: =IF($T15="H",$CE15," ") | EF15: =IF($T15="C",CB15," ") -> 0.69289177 | EG15: =IF($T15="C",CE15," ") -> -0.059447847 | EI15: =IF($T15="H",$EB15," ") | EJ15: =IF($T15="C",$EB15," ") -> 0.83150208 | EL15: {=LINEST($AB15:$AH15,$AB$6:$AH$6,TRUE,FALSE)} -> -143.78571 | EM15: 3524 | EN15: =EL15/(EL15*($AB$6+$AH$6)*0.5+EM15) -> -0.04875981 | EO15: {=LINEST($AH15:$AQ15,$AH$6:$AQ$6,TRUE,FALSE)} -> -244.63636 | EP15: 4896.6182 | EQ15: =EO15/(EO15*(AY15/2+7/2)+EP15) -> -0.11742733 | ES15: =($EM15+$EL15*ES$6-AB15)^2 -> 15678.617 | ET15: =($EM15+$EL15*ET$6-AC15)^2 -> 45186.612 | EU15: =($EM15+$EL15*EU$6-AD15)^2 -> 37774.699 | EV15: =($EM15+$EL15*EV$6-AE15)^2 -> 269509.31 | EW15: =($EM15+$EL15*EW$6-AF15)^2 -> 1785086.9 | EX15: =($EM15+$EL15*EX$6-AG15)^2 -> 661.22449 | EY15: =($EM15+$EL15*EY$6-AH15)^2 -> 259590.25 | EZ15: =($EP15+$EO15*EZ$6-AI15)^2 -> 70475.769 | FA15: =($EP15+$EO15*FA$6-AJ15)^2 -> 13714.539 | FB15: =($EP15+$EO15*FB$6-AK15)^2 -> 7875.7557 | FC15: =($EP15+$EO15*FC$6-AL15)^2 -> 12909.091 | FD15: =($EP15+$EO15*FD$6-AM15)^2 -> 104340.75 | FE15: =($EP15+$EO15*FE$6-AN15)^2 -> 64183.919 | FF15: =($EP15+$EO15*FF$6-AO15)^2 -> 1432112.6 | FG15: =($EP15+$EO15*FG$6-AP15)^2 -> 135370.48 | ... FI15: =($EP15+$EO15*FI$6-AR15)^2 -> 544348.84 | FQ15: =SQRT(AVERAGE(ES15:FI15))/AVERAGE(AB15:AR15) -> 0.22817431 | FR15: 0.051 | FS15: =FR15/FQ15 -> 0.22351333 | FV15: =SQRT(AVERAGE(ES15:EY15))/AVERAGE(AB15:AH15) -> 0.19912224 | FW15: =FR15/FV15 -> 0.25612407 | FY15: =FY14+1 -> 20 | FZ15: =COUNTIF($AY$7:$AY$106,FY15) -> 0 | GA15: =COUNTIFS($I$7:$I$106,"Fixed",$AY$7:$AY$106,$FY15) -> 0 | GB15: =COUNTIFS($I$7:$I$106,"Tracker",$AY$7:$AY$106,$FY15) -> 0
